ERROR:uvicorn.error:Exception in ASGI application
Traceback (most recent call last):
  File "C:\Users\carlo\anaconda3\envs\pasantias\lib\site-packages\uvicorn\protocols\http\h11_impl.py", line 373, in run_asgi
    result = await app(self.scope, self.receive, self.send)
  File "C:\Users\carlo\anaconda3\envs\pasantias\lib\site-packages\uvicorn\middleware\proxy_headers.py", line 75, in __call__
    return await self.app(scope, receive, send)
  File "C:\Users\carlo\anaconda3\envs\pasantias\lib\site-packages\fastapi\applications.py", line 208, in __call__
    await super().__call__(scope, receive, send)
  File "C:\Users\carlo\anaconda3\envs\pasantias\lib\site-packages\starlette\applications.py", line 112, in __call__
    await self.middleware_stack(scope, receive, send)
  File "C:\Users\carlo\anaconda3\envs\pasantias\lib\site-packages\starlette\middleware\errors.py", line 181, in __call__
    raise exc
  File "C:\Users\carlo\anaconda3\envs\pasantias\lib\site-packages\starlette\middleware\errors.py", line 159, in __call__
    await self.app(scope, receive, _send)
  File "C:\Users\carlo\anaconda3\envs\pasantias\lib\site-packages\starlette\middleware\cors.py", line 92, in __call__
    await self.simple_response(scope, receive, send, request_headers=headers)
  File "C:\Users\carlo\anaconda3\envs\pasantias\lib\site-packages\starlette\middleware\cors.py", line 147, in simple_response
    await self.app(scope, receive, send)
  File "C:\Users\carlo\anaconda3\envs\pasantias\lib\site-packages\starlette\exceptions.py", line 82, in __call__
    raise exc
  File "C:\Users\carlo\anaconda3\envs\pasantias\lib\site-packages\starlette\exceptions.py", line 71, in __call__
    await self.app(scope, receive, sender)
  File "C:\Users\carlo\anaconda3\envs\pasantias\lib\site-packages\starlette\routing.py", line 656, in __call__
    await route.handle(scope, receive, send)
  File "C:\Users\carlo\anaconda3\envs\pasantias\lib\site-packages\starlette\routing.py", line 259, in handle
    await self.app(scope, receive, send)
  File "C:\Users\carlo\anaconda3\envs\pasantias\lib\site-packages\starlette\routing.py", line 64, in app
    await response(scope, receive, send)
  File "C:\Users\carlo\anaconda3\envs\pasantias\lib\site-packages\starlette\responses.py", line 305, in __call__
    await send(
  File "C:\Users\carlo\anaconda3\envs\pasantias\lib\site-packages\starlette\exceptions.py", line 68, in sender
    await send(message)
  File "C:\Users\carlo\anaconda3\envs\pasantias\lib\site-packages\starlette\middleware\cors.py", line 153, in send
    await send(message)
  File "C:\Users\carlo\anaconda3\envs\pasantias\lib\site-packages\starlette\middleware\errors.py", line 156, in _send
    await send(message)
  File "C:\Users\carlo\anaconda3\envs\pasantias\lib\site-packages\uvicorn\protocols\http\h11_impl.py", line 477, in send
    output = self.conn.send(event)
  File "C:\Users\carlo\anaconda3\envs\pasantias\lib\site-packages\h11\_connection.py", line 468, in send
    data_list = self.send_with_data_passthrough(event)
  File "C:\Users\carlo\anaconda3\envs\pasantias\lib\site-packages\h11\_connection.py", line 501, in send_with_data_passthrough
    writer(event, data_list.append)
  File "C:\Users\carlo\anaconda3\envs\pasantias\lib\site-packages\h11\_writers.py", line 60, in __call__
    self.send_eom(event.headers, write)
  File "C:\Users\carlo\anaconda3\envs\pasantias\lib\site-packages\h11\_writers.py", line 83, in send_eom
    raise LocalProtocolError("Too little data for declared Content-Length")
h11._util.LocalProtocolError: Too little data for declared Content-Length
ERROR:uvicorn.error:Exception in ASGI application
Traceback (most recent call last):
  File "C:\Users\carlo\anaconda3\envs\pasantias\lib\site-packages\uvicorn\protocols\http\h11_impl.py", line 373, in run_asgi
    result = await app(self.scope, self.receive, self.send)
  File "C:\Users\carlo\anaconda3\envs\pasantias\lib\site-packages\uvicorn\middleware\proxy_headers.py", line 75, in __call__
    return await self.app(scope, receive, send)
  File "C:\Users\carlo\anaconda3\envs\pasantias\lib\site-packages\fastapi\applications.py", line 208, in __call__
    await super().__call__(scope, receive, send)
  File "C:\Users\carlo\anaconda3\envs\pasantias\lib\site-packages\starlette\applications.py", line 112, in __call__
    await self.middleware_stack(scope, receive, send)
  File "C:\Users\carlo\anaconda3\envs\pasantias\lib\site-packages\starlette\middleware\errors.py", line 181, in __call__
    raise exc
  File "C:\Users\carlo\anaconda3\envs\pasantias\lib\site-packages\starlette\middleware\errors.py", line 159, in __call__
    await self.app(scope, receive, _send)
  File "C:\Users\carlo\anaconda3\envs\pasantias\lib\site-packages\starlette\middleware\cors.py", line 92, in __call__
    await self.simple_response(scope, receive, send, request_headers=headers)
  File "C:\Users\carlo\anaconda3\envs\pasantias\lib\site-packages\starlette\middleware\cors.py", line 147, in simple_response
    await self.app(scope, receive, send)
  File "C:\Users\carlo\anaconda3\envs\pasantias\lib\site-packages\starlette\exceptions.py", line 82, in __call__
    raise exc
  File "C:\Users\carlo\anaconda3\envs\pasantias\lib\site-packages\starlette\exceptions.py", line 71, in __call__
    await self.app(scope, receive, sender)
  File "C:\Users\carlo\anaconda3\envs\pasantias\lib\site-packages\starlette\routing.py", line 656, in __call__
    await route.handle(scope, receive, send)
  File "C:\Users\carlo\anaconda3\envs\pasantias\lib\site-packages\starlette\routing.py", line 259, in handle
    await self.app(scope, receive, send)
  File "C:\Users\carlo\anaconda3\envs\pasantias\lib\site-packages\starlette\routing.py", line 64, in app
    await response(scope, receive, send)
  File "C:\Users\carlo\anaconda3\envs\pasantias\lib\site-packages\starlette\responses.py", line 305, in __call__
    await send(
  File "C:\Users\carlo\anaconda3\envs\pasantias\lib\site-packages\starlette\exceptions.py", line 68, in sender
    await send(message)
  File "C:\Users\carlo\anaconda3\envs\pasantias\lib\site-packages\starlette\middleware\cors.py", line 153, in send
    await send(message)
  File "C:\Users\carlo\anaconda3\envs\pasantias\lib\site-packages\starlette\middleware\errors.py", line 156, in _send
    await send(message)
  File "C:\Users\carlo\anaconda3\envs\pasantias\lib\site-packages\uvicorn\protocols\http\h11_impl.py", line 477, in send
    output = self.conn.send(event)
  File "C:\Users\carlo\anaconda3\envs\pasantias\lib\site-packages\h11\_connection.py", line 468, in send
    data_list = self.send_with_data_passthrough(event)
  File "C:\Users\carlo\anaconda3\envs\pasantias\lib\site-packages\h11\_connection.py", line 501, in send_with_data_passthrough
    writer(event, data_list.append)
  File "C:\Users\carlo\anaconda3\envs\pasantias\lib\site-packages\h11\_writers.py", line 60, in __call__
    self.send_eom(event.headers, write)
  File "C:\Users\carlo\anaconda3\envs\pasantias\lib\site-packages\h11\_writers.py", line 83, in send_eom
    raise LocalProtocolError("Too little data for declared Content-Length")
h11._util.LocalProtocolError: Too little data for declared Content-Length
ERROR:root: Error: 'NoneType' object has no attribute 'copy'
ERROR:uvicorn.error:Exception in ASGI application
Traceback (most recent call last):
  File "C:\Users\carlo\anaconda3\envs\pasantias\lib\site-packages\uvicorn\protocols\http\h11_impl.py", line 373, in run_asgi
    result = await app(self.scope, self.receive, self.send)
  File "C:\Users\carlo\anaconda3\envs\pasantias\lib\site-packages\uvicorn\middleware\proxy_headers.py", line 75, in __call__
    return await self.app(scope, receive, send)
  File "C:\Users\carlo\anaconda3\envs\pasantias\lib\site-packages\fastapi\applications.py", line 208, in __call__
    await super().__call__(scope, receive, send)
  File "C:\Users\carlo\anaconda3\envs\pasantias\lib\site-packages\starlette\applications.py", line 112, in __call__
    await self.middleware_stack(scope, receive, send)
  File "C:\Users\carlo\anaconda3\envs\pasantias\lib\site-packages\starlette\middleware\errors.py", line 181, in __call__
    raise exc
  File "C:\Users\carlo\anaconda3\envs\pasantias\lib\site-packages\starlette\middleware\errors.py", line 159, in __call__
    await self.app(scope, receive, _send)
  File "C:\Users\carlo\anaconda3\envs\pasantias\lib\site-packages\starlette\middleware\cors.py", line 92, in __call__
    await self.simple_response(scope, receive, send, request_headers=headers)
  File "C:\Users\carlo\anaconda3\envs\pasantias\lib\site-packages\starlette\middleware\cors.py", line 147, in simple_response
    await self.app(scope, receive, send)
  File "C:\Users\carlo\anaconda3\envs\pasantias\lib\site-packages\starlette\exceptions.py", line 82, in __call__
    raise exc
  File "C:\Users\carlo\anaconda3\envs\pasantias\lib\site-packages\starlette\exceptions.py", line 71, in __call__
    await self.app(scope, receive, sender)
  File "C:\Users\carlo\anaconda3\envs\pasantias\lib\site-packages\starlette\routing.py", line 656, in __call__
    await route.handle(scope, receive, send)
  File "C:\Users\carlo\anaconda3\envs\pasantias\lib\site-packages\starlette\routing.py", line 259, in handle
    await self.app(scope, receive, send)
  File "C:\Users\carlo\anaconda3\envs\pasantias\lib\site-packages\starlette\routing.py", line 61, in app
    response = await func(request)
  File "C:\Users\carlo\anaconda3\envs\pasantias\lib\site-packages\fastapi\routing.py", line 226, in app
    raw_response = await run_endpoint_function(
  File "C:\Users\carlo\anaconda3\envs\pasantias\lib\site-packages\fastapi\routing.py", line 159, in run_endpoint_function
    return await dependant.call(**values)
  File "C:\Users\carlo\Documents\GitHub\LompadS-Backend\.\main.py", line 91, in read_file
    return {'DATA': FileController.load_recursive_model(xml_manifest, hashed_code)}
  File "C:\Users\carlo\Documents\GitHub\LompadS-Backend\.\controller\FileController.py", line 193, in load_recursive_model
    lom_controller.map_recursively(parsed_dictionary, is_lompad_exported=is_lompad_exported)
  File "C:\Users\carlo\Documents\GitHub\LompadS-Backend\.\controller\LOMController.py", line 41, in map_recursively
    self.map_recursively(dictionary[key], is_lompad_exported)
  File "C:\Users\carlo\Documents\GitHub\LompadS-Backend\.\controller\LOMController.py", line 39, in map_recursively
    self._mapped_data[key], self._object_dict[key] = LOMModel.determine_lompad_leaf(dictionary[key], str(key),
TypeError: cannot unpack non-iterable NoneType object
ERROR:uvicorn.error:Exception in ASGI application
Traceback (most recent call last):
  File "C:\Users\carlo\anaconda3\envs\pasantias\lib\site-packages\uvicorn\protocols\http\h11_impl.py", line 373, in run_asgi
    result = await app(self.scope, self.receive, self.send)
  File "C:\Users\carlo\anaconda3\envs\pasantias\lib\site-packages\uvicorn\middleware\proxy_headers.py", line 75, in __call__
    return await self.app(scope, receive, send)
  File "C:\Users\carlo\anaconda3\envs\pasantias\lib\site-packages\fastapi\applications.py", line 208, in __call__
    await super().__call__(scope, receive, send)
  File "C:\Users\carlo\anaconda3\envs\pasantias\lib\site-packages\starlette\applications.py", line 112, in __call__
    await self.middleware_stack(scope, receive, send)
  File "C:\Users\carlo\anaconda3\envs\pasantias\lib\site-packages\starlette\middleware\errors.py", line 181, in __call__
    raise exc
  File "C:\Users\carlo\anaconda3\envs\pasantias\lib\site-packages\starlette\middleware\errors.py", line 159, in __call__
    await self.app(scope, receive, _send)
  File "C:\Users\carlo\anaconda3\envs\pasantias\lib\site-packages\starlette\middleware\cors.py", line 92, in __call__
    await self.simple_response(scope, receive, send, request_headers=headers)
  File "C:\Users\carlo\anaconda3\envs\pasantias\lib\site-packages\starlette\middleware\cors.py", line 147, in simple_response
    await self.app(scope, receive, send)
  File "C:\Users\carlo\anaconda3\envs\pasantias\lib\site-packages\starlette\exceptions.py", line 82, in __call__
    raise exc
  File "C:\Users\carlo\anaconda3\envs\pasantias\lib\site-packages\starlette\exceptions.py", line 71, in __call__
    await self.app(scope, receive, sender)
  File "C:\Users\carlo\anaconda3\envs\pasantias\lib\site-packages\starlette\routing.py", line 656, in __call__
    await route.handle(scope, receive, send)
  File "C:\Users\carlo\anaconda3\envs\pasantias\lib\site-packages\starlette\routing.py", line 259, in handle
    await self.app(scope, receive, send)
  File "C:\Users\carlo\anaconda3\envs\pasantias\lib\site-packages\starlette\routing.py", line 61, in app
    response = await func(request)
  File "C:\Users\carlo\anaconda3\envs\pasantias\lib\site-packages\fastapi\routing.py", line 226, in app
    raw_response = await run_endpoint_function(
  File "C:\Users\carlo\anaconda3\envs\pasantias\lib\site-packages\fastapi\routing.py", line 161, in run_endpoint_function
    return await run_in_threadpool(dependant.call, **values)
  File "C:\Users\carlo\anaconda3\envs\pasantias\lib\site-packages\starlette\concurrency.py", line 39, in run_in_threadpool
    return await anyio.to_thread.run_sync(func, *args)
  File "C:\Users\carlo\anaconda3\envs\pasantias\lib\site-packages\anyio\to_thread.py", line 28, in run_sync
    return await get_asynclib().run_sync_in_worker_thread(func, *args, cancellable=cancellable,
  File "C:\Users\carlo\anaconda3\envs\pasantias\lib\site-packages\anyio\_backends\_asyncio.py", line 805, in run_sync_in_worker_thread
    return await future
  File "C:\Users\carlo\anaconda3\envs\pasantias\lib\site-packages\anyio\_backends\_asyncio.py", line 743, in run
    result = func(*args)
  File "C:\Users\carlo\Documents\GitHub\LompadS-Backend\.\main.py", line 114, in get_file
    FileController.write_data(''.join(open(f'./temp_files/{hashed_code}_exported.xml')).strip(),
FileNotFoundError: [Errno 2] No such file or directory: './temp_files/OA_Zotero_Scorm_-1049755356770141196_exported.xml'
ERROR:root: Error: 'NoneType' object has no attribute 'copy'
ERROR:uvicorn.error:Exception in ASGI application
Traceback (most recent call last):
  File "C:\Users\carlo\anaconda3\envs\pasantias\lib\site-packages\uvicorn\protocols\http\h11_impl.py", line 373, in run_asgi
    result = await app(self.scope, self.receive, self.send)
  File "C:\Users\carlo\anaconda3\envs\pasantias\lib\site-packages\uvicorn\middleware\proxy_headers.py", line 75, in __call__
    return await self.app(scope, receive, send)
  File "C:\Users\carlo\anaconda3\envs\pasantias\lib\site-packages\fastapi\applications.py", line 208, in __call__
    await super().__call__(scope, receive, send)
  File "C:\Users\carlo\anaconda3\envs\pasantias\lib\site-packages\starlette\applications.py", line 112, in __call__
    await self.middleware_stack(scope, receive, send)
  File "C:\Users\carlo\anaconda3\envs\pasantias\lib\site-packages\starlette\middleware\errors.py", line 181, in __call__
    raise exc
  File "C:\Users\carlo\anaconda3\envs\pasantias\lib\site-packages\starlette\middleware\errors.py", line 159, in __call__
    await self.app(scope, receive, _send)
  File "C:\Users\carlo\anaconda3\envs\pasantias\lib\site-packages\starlette\middleware\cors.py", line 92, in __call__
    await self.simple_response(scope, receive, send, request_headers=headers)
  File "C:\Users\carlo\anaconda3\envs\pasantias\lib\site-packages\starlette\middleware\cors.py", line 147, in simple_response
    await self.app(scope, receive, send)
  File "C:\Users\carlo\anaconda3\envs\pasantias\lib\site-packages\starlette\exceptions.py", line 82, in __call__
    raise exc
  File "C:\Users\carlo\anaconda3\envs\pasantias\lib\site-packages\starlette\exceptions.py", line 71, in __call__
    await self.app(scope, receive, sender)
  File "C:\Users\carlo\anaconda3\envs\pasantias\lib\site-packages\starlette\routing.py", line 656, in __call__
    await route.handle(scope, receive, send)
  File "C:\Users\carlo\anaconda3\envs\pasantias\lib\site-packages\starlette\routing.py", line 259, in handle
    await self.app(scope, receive, send)
  File "C:\Users\carlo\anaconda3\envs\pasantias\lib\site-packages\starlette\routing.py", line 61, in app
    response = await func(request)
  File "C:\Users\carlo\anaconda3\envs\pasantias\lib\site-packages\fastapi\routing.py", line 226, in app
    raw_response = await run_endpoint_function(
  File "C:\Users\carlo\anaconda3\envs\pasantias\lib\site-packages\fastapi\routing.py", line 159, in run_endpoint_function
    return await dependant.call(**values)
  File "C:\Users\carlo\Documents\GitHub\LompadS-Backend\.\main.py", line 91, in read_file
    return {'DATA': FileController.load_recursive_model(xml_manifest, hashed_code)}
  File "C:\Users\carlo\Documents\GitHub\LompadS-Backend\.\controller\FileController.py", line 193, in load_recursive_model
    lom_controller.map_recursively(parsed_dictionary, is_lompad_exported=is_lompad_exported)
  File "C:\Users\carlo\Documents\GitHub\LompadS-Backend\.\controller\LOMController.py", line 41, in map_recursively
    self.map_recursively(dictionary[key], is_lompad_exported)
  File "C:\Users\carlo\Documents\GitHub\LompadS-Backend\.\controller\LOMController.py", line 39, in map_recursively
    self._mapped_data[key], self._object_dict[key] = LOMModel.determine_lompad_leaf(dictionary[key], str(key),
TypeError: cannot unpack non-iterable NoneType object
ERROR:uvicorn.error:Exception in ASGI application
Traceback (most recent call last):
  File "C:\Users\carlo\anaconda3\envs\pasantias\lib\site-packages\uvicorn\protocols\http\h11_impl.py", line 373, in run_asgi
    result = await app(self.scope, self.receive, self.send)
  File "C:\Users\carlo\anaconda3\envs\pasantias\lib\site-packages\uvicorn\middleware\proxy_headers.py", line 75, in __call__
    return await self.app(scope, receive, send)
  File "C:\Users\carlo\anaconda3\envs\pasantias\lib\site-packages\fastapi\applications.py", line 208, in __call__
    await super().__call__(scope, receive, send)
  File "C:\Users\carlo\anaconda3\envs\pasantias\lib\site-packages\starlette\applications.py", line 112, in __call__
    await self.middleware_stack(scope, receive, send)
  File "C:\Users\carlo\anaconda3\envs\pasantias\lib\site-packages\starlette\middleware\errors.py", line 181, in __call__
    raise exc
  File "C:\Users\carlo\anaconda3\envs\pasantias\lib\site-packages\starlette\middleware\errors.py", line 159, in __call__
    await self.app(scope, receive, _send)
  File "C:\Users\carlo\anaconda3\envs\pasantias\lib\site-packages\starlette\middleware\cors.py", line 92, in __call__
    await self.simple_response(scope, receive, send, request_headers=headers)
  File "C:\Users\carlo\anaconda3\envs\pasantias\lib\site-packages\starlette\middleware\cors.py", line 147, in simple_response
    await self.app(scope, receive, send)
  File "C:\Users\carlo\anaconda3\envs\pasantias\lib\site-packages\starlette\exceptions.py", line 82, in __call__
    raise exc
  File "C:\Users\carlo\anaconda3\envs\pasantias\lib\site-packages\starlette\exceptions.py", line 71, in __call__
    await self.app(scope, receive, sender)
  File "C:\Users\carlo\anaconda3\envs\pasantias\lib\site-packages\starlette\routing.py", line 656, in __call__
    await route.handle(scope, receive, send)
  File "C:\Users\carlo\anaconda3\envs\pasantias\lib\site-packages\starlette\routing.py", line 259, in handle
    await self.app(scope, receive, send)
  File "C:\Users\carlo\anaconda3\envs\pasantias\lib\site-packages\starlette\routing.py", line 61, in app
    response = await func(request)
  File "C:\Users\carlo\anaconda3\envs\pasantias\lib\site-packages\fastapi\routing.py", line 226, in app
    raw_response = await run_endpoint_function(
  File "C:\Users\carlo\anaconda3\envs\pasantias\lib\site-packages\fastapi\routing.py", line 161, in run_endpoint_function
    return await run_in_threadpool(dependant.call, **values)
  File "C:\Users\carlo\anaconda3\envs\pasantias\lib\site-packages\starlette\concurrency.py", line 39, in run_in_threadpool
    return await anyio.to_thread.run_sync(func, *args)
  File "C:\Users\carlo\anaconda3\envs\pasantias\lib\site-packages\anyio\to_thread.py", line 28, in run_sync
    return await get_asynclib().run_sync_in_worker_thread(func, *args, cancellable=cancellable,
  File "C:\Users\carlo\anaconda3\envs\pasantias\lib\site-packages\anyio\_backends\_asyncio.py", line 805, in run_sync_in_worker_thread
    return await future
  File "C:\Users\carlo\anaconda3\envs\pasantias\lib\site-packages\anyio\_backends\_asyncio.py", line 743, in run
    result = func(*args)
  File "C:\Users\carlo\Documents\GitHub\LompadS-Backend\.\main.py", line 114, in get_file
    FileController.write_data(''.join(open(f'./temp_files/{hashed_code}_exported.xml')).strip(),
FileNotFoundError: [Errno 2] No such file or directory: './temp_files/OA_Zotero_Scorm_-6767687096604768053_exported.xml'
INFO:uvicorn.error:Shutting down
ERROR:uvicorn.error:Exception in ASGI application
Traceback (most recent call last):
  File "C:\Users\carlo\anaconda3\envs\pasantias\lib\site-packages\uvicorn\protocols\http\h11_impl.py", line 373, in run_asgi
    result = await app(self.scope, self.receive, self.send)
  File "C:\Users\carlo\anaconda3\envs\pasantias\lib\site-packages\uvicorn\middleware\proxy_headers.py", line 75, in __call__
    return await self.app(scope, receive, send)
  File "C:\Users\carlo\anaconda3\envs\pasantias\lib\site-packages\fastapi\applications.py", line 208, in __call__
    await super().__call__(scope, receive, send)
  File "C:\Users\carlo\anaconda3\envs\pasantias\lib\site-packages\starlette\applications.py", line 112, in __call__
    await self.middleware_stack(scope, receive, send)
  File "C:\Users\carlo\anaconda3\envs\pasantias\lib\site-packages\starlette\middleware\errors.py", line 181, in __call__
    raise exc
  File "C:\Users\carlo\anaconda3\envs\pasantias\lib\site-packages\starlette\middleware\errors.py", line 159, in __call__
    await self.app(scope, receive, _send)
  File "C:\Users\carlo\anaconda3\envs\pasantias\lib\site-packages\starlette\middleware\cors.py", line 92, in __call__
    await self.simple_response(scope, receive, send, request_headers=headers)
  File "C:\Users\carlo\anaconda3\envs\pasantias\lib\site-packages\starlette\middleware\cors.py", line 147, in simple_response
    await self.app(scope, receive, send)
  File "C:\Users\carlo\anaconda3\envs\pasantias\lib\site-packages\starlette\exceptions.py", line 82, in __call__
    raise exc
  File "C:\Users\carlo\anaconda3\envs\pasantias\lib\site-packages\starlette\exceptions.py", line 71, in __call__
    await self.app(scope, receive, sender)
  File "C:\Users\carlo\anaconda3\envs\pasantias\lib\site-packages\starlette\routing.py", line 656, in __call__
    await route.handle(scope, receive, send)
  File "C:\Users\carlo\anaconda3\envs\pasantias\lib\site-packages\starlette\routing.py", line 259, in handle
    await self.app(scope, receive, send)
  File "C:\Users\carlo\anaconda3\envs\pasantias\lib\site-packages\starlette\routing.py", line 64, in app
    await response(scope, receive, send)
  File "C:\Users\carlo\anaconda3\envs\pasantias\lib\site-packages\starlette\responses.py", line 305, in __call__
    await send(
  File "C:\Users\carlo\anaconda3\envs\pasantias\lib\site-packages\starlette\exceptions.py", line 68, in sender
    await send(message)
  File "C:\Users\carlo\anaconda3\envs\pasantias\lib\site-packages\starlette\middleware\cors.py", line 153, in send
    await send(message)
  File "C:\Users\carlo\anaconda3\envs\pasantias\lib\site-packages\starlette\middleware\errors.py", line 156, in _send
    await send(message)
  File "C:\Users\carlo\anaconda3\envs\pasantias\lib\site-packages\uvicorn\protocols\http\h11_impl.py", line 477, in send
    output = self.conn.send(event)
  File "C:\Users\carlo\anaconda3\envs\pasantias\lib\site-packages\h11\_connection.py", line 468, in send
    data_list = self.send_with_data_passthrough(event)
  File "C:\Users\carlo\anaconda3\envs\pasantias\lib\site-packages\h11\_connection.py", line 501, in send_with_data_passthrough
    writer(event, data_list.append)
  File "C:\Users\carlo\anaconda3\envs\pasantias\lib\site-packages\h11\_writers.py", line 60, in __call__
    self.send_eom(event.headers, write)
  File "C:\Users\carlo\anaconda3\envs\pasantias\lib\site-packages\h11\_writers.py", line 83, in send_eom
    raise LocalProtocolError("Too little data for declared Content-Length")
h11._util.LocalProtocolError: Too little data for declared Content-Length
ERROR:uvicorn.error:Exception in ASGI application
Traceback (most recent call last):
  File "C:\Users\carlo\anaconda3\envs\pasantias\lib\site-packages\uvicorn\protocols\http\h11_impl.py", line 373, in run_asgi
    result = await app(self.scope, self.receive, self.send)
  File "C:\Users\carlo\anaconda3\envs\pasantias\lib\site-packages\uvicorn\middleware\proxy_headers.py", line 75, in __call__
    return await self.app(scope, receive, send)
  File "C:\Users\carlo\anaconda3\envs\pasantias\lib\site-packages\fastapi\applications.py", line 208, in __call__
    await super().__call__(scope, receive, send)
  File "C:\Users\carlo\anaconda3\envs\pasantias\lib\site-packages\starlette\applications.py", line 112, in __call__
    await self.middleware_stack(scope, receive, send)
  File "C:\Users\carlo\anaconda3\envs\pasantias\lib\site-packages\starlette\middleware\errors.py", line 181, in __call__
    raise exc
  File "C:\Users\carlo\anaconda3\envs\pasantias\lib\site-packages\starlette\middleware\errors.py", line 159, in __call__
    await self.app(scope, receive, _send)
  File "C:\Users\carlo\anaconda3\envs\pasantias\lib\site-packages\starlette\middleware\cors.py", line 92, in __call__
    await self.simple_response(scope, receive, send, request_headers=headers)
  File "C:\Users\carlo\anaconda3\envs\pasantias\lib\site-packages\starlette\middleware\cors.py", line 147, in simple_response
    await self.app(scope, receive, send)
  File "C:\Users\carlo\anaconda3\envs\pasantias\lib\site-packages\starlette\exceptions.py", line 82, in __call__
    raise exc
  File "C:\Users\carlo\anaconda3\envs\pasantias\lib\site-packages\starlette\exceptions.py", line 71, in __call__
    await self.app(scope, receive, sender)
  File "C:\Users\carlo\anaconda3\envs\pasantias\lib\site-packages\starlette\routing.py", line 656, in __call__
    await route.handle(scope, receive, send)
  File "C:\Users\carlo\anaconda3\envs\pasantias\lib\site-packages\starlette\routing.py", line 259, in handle
    await self.app(scope, receive, send)
  File "C:\Users\carlo\anaconda3\envs\pasantias\lib\site-packages\starlette\routing.py", line 64, in app
    await response(scope, receive, send)
  File "C:\Users\carlo\anaconda3\envs\pasantias\lib\site-packages\starlette\responses.py", line 305, in __call__
    await send(
  File "C:\Users\carlo\anaconda3\envs\pasantias\lib\site-packages\starlette\exceptions.py", line 68, in sender
    await send(message)
  File "C:\Users\carlo\anaconda3\envs\pasantias\lib\site-packages\starlette\middleware\cors.py", line 153, in send
    await send(message)
  File "C:\Users\carlo\anaconda3\envs\pasantias\lib\site-packages\starlette\middleware\errors.py", line 156, in _send
    await send(message)
  File "C:\Users\carlo\anaconda3\envs\pasantias\lib\site-packages\uvicorn\protocols\http\h11_impl.py", line 477, in send
    output = self.conn.send(event)
  File "C:\Users\carlo\anaconda3\envs\pasantias\lib\site-packages\h11\_connection.py", line 468, in send
    data_list = self.send_with_data_passthrough(event)
  File "C:\Users\carlo\anaconda3\envs\pasantias\lib\site-packages\h11\_connection.py", line 501, in send_with_data_passthrough
    writer(event, data_list.append)
  File "C:\Users\carlo\anaconda3\envs\pasantias\lib\site-packages\h11\_writers.py", line 60, in __call__
    self.send_eom(event.headers, write)
  File "C:\Users\carlo\anaconda3\envs\pasantias\lib\site-packages\h11\_writers.py", line 83, in send_eom
    raise LocalProtocolError("Too little data for declared Content-Length")
h11._util.LocalProtocolError: Too little data for declared Content-Length
ERROR:uvicorn.error:Exception in ASGI application
Traceback (most recent call last):
  File "C:\Users\carlo\anaconda3\envs\pasantias\lib\site-packages\uvicorn\protocols\http\h11_impl.py", line 373, in run_asgi
    result = await app(self.scope, self.receive, self.send)
  File "C:\Users\carlo\anaconda3\envs\pasantias\lib\site-packages\uvicorn\middleware\proxy_headers.py", line 75, in __call__
    return await self.app(scope, receive, send)
  File "C:\Users\carlo\anaconda3\envs\pasantias\lib\site-packages\fastapi\applications.py", line 208, in __call__
    await super().__call__(scope, receive, send)
  File "C:\Users\carlo\anaconda3\envs\pasantias\lib\site-packages\starlette\applications.py", line 112, in __call__
    await self.middleware_stack(scope, receive, send)
  File "C:\Users\carlo\anaconda3\envs\pasantias\lib\site-packages\starlette\middleware\errors.py", line 181, in __call__
    raise exc
  File "C:\Users\carlo\anaconda3\envs\pasantias\lib\site-packages\starlette\middleware\errors.py", line 159, in __call__
    await self.app(scope, receive, _send)
  File "C:\Users\carlo\anaconda3\envs\pasantias\lib\site-packages\starlette\middleware\cors.py", line 92, in __call__
    await self.simple_response(scope, receive, send, request_headers=headers)
  File "C:\Users\carlo\anaconda3\envs\pasantias\lib\site-packages\starlette\middleware\cors.py", line 147, in simple_response
    await self.app(scope, receive, send)
  File "C:\Users\carlo\anaconda3\envs\pasantias\lib\site-packages\starlette\exceptions.py", line 82, in __call__
    raise exc
  File "C:\Users\carlo\anaconda3\envs\pasantias\lib\site-packages\starlette\exceptions.py", line 71, in __call__
    await self.app(scope, receive, sender)
  File "C:\Users\carlo\anaconda3\envs\pasantias\lib\site-packages\starlette\routing.py", line 656, in __call__
    await route.handle(scope, receive, send)
  File "C:\Users\carlo\anaconda3\envs\pasantias\lib\site-packages\starlette\routing.py", line 259, in handle
    await self.app(scope, receive, send)
  File "C:\Users\carlo\anaconda3\envs\pasantias\lib\site-packages\starlette\routing.py", line 64, in app
    await response(scope, receive, send)
  File "C:\Users\carlo\anaconda3\envs\pasantias\lib\site-packages\starlette\responses.py", line 305, in __call__
    await send(
  File "C:\Users\carlo\anaconda3\envs\pasantias\lib\site-packages\starlette\exceptions.py", line 68, in sender
    await send(message)
  File "C:\Users\carlo\anaconda3\envs\pasantias\lib\site-packages\starlette\middleware\cors.py", line 153, in send
    await send(message)
  File "C:\Users\carlo\anaconda3\envs\pasantias\lib\site-packages\starlette\middleware\errors.py", line 156, in _send
    await send(message)
  File "C:\Users\carlo\anaconda3\envs\pasantias\lib\site-packages\uvicorn\protocols\http\h11_impl.py", line 477, in send
    output = self.conn.send(event)
  File "C:\Users\carlo\anaconda3\envs\pasantias\lib\site-packages\h11\_connection.py", line 468, in send
    data_list = self.send_with_data_passthrough(event)
  File "C:\Users\carlo\anaconda3\envs\pasantias\lib\site-packages\h11\_connection.py", line 501, in send_with_data_passthrough
    writer(event, data_list.append)
  File "C:\Users\carlo\anaconda3\envs\pasantias\lib\site-packages\h11\_writers.py", line 60, in __call__
    self.send_eom(event.headers, write)
  File "C:\Users\carlo\anaconda3\envs\pasantias\lib\site-packages\h11\_writers.py", line 83, in send_eom
    raise LocalProtocolError("Too little data for declared Content-Length")
h11._util.LocalProtocolError: Too little data for declared Content-Length
ERROR:uvicorn.error:Exception in ASGI application
Traceback (most recent call last):
  File "C:\Users\carlo\anaconda3\envs\pasantias\lib\site-packages\uvicorn\protocols\http\h11_impl.py", line 373, in run_asgi
    result = await app(self.scope, self.receive, self.send)
  File "C:\Users\carlo\anaconda3\envs\pasantias\lib\site-packages\uvicorn\middleware\proxy_headers.py", line 75, in __call__
    return await self.app(scope, receive, send)
  File "C:\Users\carlo\anaconda3\envs\pasantias\lib\site-packages\fastapi\applications.py", line 208, in __call__
    await super().__call__(scope, receive, send)
  File "C:\Users\carlo\anaconda3\envs\pasantias\lib\site-packages\starlette\applications.py", line 112, in __call__
    await self.middleware_stack(scope, receive, send)
  File "C:\Users\carlo\anaconda3\envs\pasantias\lib\site-packages\starlette\middleware\errors.py", line 181, in __call__
    raise exc
  File "C:\Users\carlo\anaconda3\envs\pasantias\lib\site-packages\starlette\middleware\errors.py", line 159, in __call__
    await self.app(scope, receive, _send)
  File "C:\Users\carlo\anaconda3\envs\pasantias\lib\site-packages\starlette\middleware\cors.py", line 92, in __call__
    await self.simple_response(scope, receive, send, request_headers=headers)
  File "C:\Users\carlo\anaconda3\envs\pasantias\lib\site-packages\starlette\middleware\cors.py", line 147, in simple_response
    await self.app(scope, receive, send)
  File "C:\Users\carlo\anaconda3\envs\pasantias\lib\site-packages\starlette\exceptions.py", line 82, in __call__
    raise exc
  File "C:\Users\carlo\anaconda3\envs\pasantias\lib\site-packages\starlette\exceptions.py", line 71, in __call__
    await self.app(scope, receive, sender)
  File "C:\Users\carlo\anaconda3\envs\pasantias\lib\site-packages\starlette\routing.py", line 656, in __call__
    await route.handle(scope, receive, send)
  File "C:\Users\carlo\anaconda3\envs\pasantias\lib\site-packages\starlette\routing.py", line 259, in handle
    await self.app(scope, receive, send)
  File "C:\Users\carlo\anaconda3\envs\pasantias\lib\site-packages\starlette\routing.py", line 64, in app
    await response(scope, receive, send)
  File "C:\Users\carlo\anaconda3\envs\pasantias\lib\site-packages\starlette\responses.py", line 305, in __call__
    await send(
  File "C:\Users\carlo\anaconda3\envs\pasantias\lib\site-packages\starlette\exceptions.py", line 68, in sender
    await send(message)
  File "C:\Users\carlo\anaconda3\envs\pasantias\lib\site-packages\starlette\middleware\cors.py", line 153, in send
    await send(message)
  File "C:\Users\carlo\anaconda3\envs\pasantias\lib\site-packages\starlette\middleware\errors.py", line 156, in _send
    await send(message)
  File "C:\Users\carlo\anaconda3\envs\pasantias\lib\site-packages\uvicorn\protocols\http\h11_impl.py", line 477, in send
    output = self.conn.send(event)
  File "C:\Users\carlo\anaconda3\envs\pasantias\lib\site-packages\h11\_connection.py", line 468, in send
    data_list = self.send_with_data_passthrough(event)
  File "C:\Users\carlo\anaconda3\envs\pasantias\lib\site-packages\h11\_connection.py", line 501, in send_with_data_passthrough
    writer(event, data_list.append)
  File "C:\Users\carlo\anaconda3\envs\pasantias\lib\site-packages\h11\_writers.py", line 60, in __call__
    self.send_eom(event.headers, write)
  File "C:\Users\carlo\anaconda3\envs\pasantias\lib\site-packages\h11\_writers.py", line 83, in send_eom
    raise LocalProtocolError("Too little data for declared Content-Length")
h11._util.LocalProtocolError: Too little data for declared Content-Length
ERROR:uvicorn.error:Exception in ASGI application
Traceback (most recent call last):
  File "C:\Users\carlo\anaconda3\envs\pasantias\lib\site-packages\uvicorn\protocols\http\h11_impl.py", line 373, in run_asgi
    result = await app(self.scope, self.receive, self.send)
  File "C:\Users\carlo\anaconda3\envs\pasantias\lib\site-packages\uvicorn\middleware\proxy_headers.py", line 75, in __call__
    return await self.app(scope, receive, send)
  File "C:\Users\carlo\anaconda3\envs\pasantias\lib\site-packages\fastapi\applications.py", line 208, in __call__
    await super().__call__(scope, receive, send)
  File "C:\Users\carlo\anaconda3\envs\pasantias\lib\site-packages\starlette\applications.py", line 112, in __call__
    await self.middleware_stack(scope, receive, send)
  File "C:\Users\carlo\anaconda3\envs\pasantias\lib\site-packages\starlette\middleware\errors.py", line 181, in __call__
    raise exc
  File "C:\Users\carlo\anaconda3\envs\pasantias\lib\site-packages\starlette\middleware\errors.py", line 159, in __call__
    await self.app(scope, receive, _send)
  File "C:\Users\carlo\anaconda3\envs\pasantias\lib\site-packages\starlette\middleware\cors.py", line 92, in __call__
    await self.simple_response(scope, receive, send, request_headers=headers)
  File "C:\Users\carlo\anaconda3\envs\pasantias\lib\site-packages\starlette\middleware\cors.py", line 147, in simple_response
    await self.app(scope, receive, send)
  File "C:\Users\carlo\anaconda3\envs\pasantias\lib\site-packages\starlette\exceptions.py", line 82, in __call__
    raise exc
  File "C:\Users\carlo\anaconda3\envs\pasantias\lib\site-packages\starlette\exceptions.py", line 71, in __call__
    await self.app(scope, receive, sender)
  File "C:\Users\carlo\anaconda3\envs\pasantias\lib\site-packages\starlette\routing.py", line 656, in __call__
    await route.handle(scope, receive, send)
  File "C:\Users\carlo\anaconda3\envs\pasantias\lib\site-packages\starlette\routing.py", line 259, in handle
    await self.app(scope, receive, send)
  File "C:\Users\carlo\anaconda3\envs\pasantias\lib\site-packages\starlette\routing.py", line 61, in app
    response = await func(request)
  File "C:\Users\carlo\anaconda3\envs\pasantias\lib\site-packages\fastapi\routing.py", line 226, in app
    raw_response = await run_endpoint_function(
  File "C:\Users\carlo\anaconda3\envs\pasantias\lib\site-packages\fastapi\routing.py", line 159, in run_endpoint_function
    return await dependant.call(**values)
  File "C:\Users\carlo\Documents\GitHub\LompadS-Backend\.\main.py", line 91, in read_file
    return {'DATA': FileController.load_recursive_model(xml_manifest, hashed_code)}
  File "C:\Users\carlo\Documents\GitHub\LompadS-Backend\.\controller\FileController.py", line 197, in load_recursive_model
    lom_controller.map_recursively(parsed_dictionary, is_lompad_exported=is_lompad_exported)
  File "C:\Users\carlo\Documents\GitHub\LompadS-Backend\.\controller\LOMController.py", line 43, in map_recursively
    self.map_recursively(dictionary[key], is_lompad_exported)
  File "C:\Users\carlo\Documents\GitHub\LompadS-Backend\.\controller\LOMController.py", line 40, in map_recursively
    self._mapped_data[key], self._object_dict[key] = LOMModel.determine_lompad_leaf(dictionary[key], str(key),
TypeError: cannot unpack non-iterable NoneType object
ERROR:uvicorn.error:Exception in ASGI application
Traceback (most recent call last):
  File "C:\Users\carlo\anaconda3\envs\pasantias\lib\site-packages\uvicorn\protocols\http\h11_impl.py", line 373, in run_asgi
    result = await app(self.scope, self.receive, self.send)
  File "C:\Users\carlo\anaconda3\envs\pasantias\lib\site-packages\uvicorn\middleware\proxy_headers.py", line 75, in __call__
    return await self.app(scope, receive, send)
  File "C:\Users\carlo\anaconda3\envs\pasantias\lib\site-packages\fastapi\applications.py", line 208, in __call__
    await super().__call__(scope, receive, send)
  File "C:\Users\carlo\anaconda3\envs\pasantias\lib\site-packages\starlette\applications.py", line 112, in __call__
    await self.middleware_stack(scope, receive, send)
  File "C:\Users\carlo\anaconda3\envs\pasantias\lib\site-packages\starlette\middleware\errors.py", line 181, in __call__
    raise exc
  File "C:\Users\carlo\anaconda3\envs\pasantias\lib\site-packages\starlette\middleware\errors.py", line 159, in __call__
    await self.app(scope, receive, _send)
  File "C:\Users\carlo\anaconda3\envs\pasantias\lib\site-packages\starlette\middleware\cors.py", line 92, in __call__
    await self.simple_response(scope, receive, send, request_headers=headers)
  File "C:\Users\carlo\anaconda3\envs\pasantias\lib\site-packages\starlette\middleware\cors.py", line 147, in simple_response
    await self.app(scope, receive, send)
  File "C:\Users\carlo\anaconda3\envs\pasantias\lib\site-packages\starlette\exceptions.py", line 82, in __call__
    raise exc
  File "C:\Users\carlo\anaconda3\envs\pasantias\lib\site-packages\starlette\exceptions.py", line 71, in __call__
    await self.app(scope, receive, sender)
  File "C:\Users\carlo\anaconda3\envs\pasantias\lib\site-packages\starlette\routing.py", line 656, in __call__
    await route.handle(scope, receive, send)
  File "C:\Users\carlo\anaconda3\envs\pasantias\lib\site-packages\starlette\routing.py", line 259, in handle
    await self.app(scope, receive, send)
  File "C:\Users\carlo\anaconda3\envs\pasantias\lib\site-packages\starlette\routing.py", line 61, in app
    response = await func(request)
  File "C:\Users\carlo\anaconda3\envs\pasantias\lib\site-packages\fastapi\routing.py", line 226, in app
    raw_response = await run_endpoint_function(
  File "C:\Users\carlo\anaconda3\envs\pasantias\lib\site-packages\fastapi\routing.py", line 161, in run_endpoint_function
    return await run_in_threadpool(dependant.call, **values)
  File "C:\Users\carlo\anaconda3\envs\pasantias\lib\site-packages\starlette\concurrency.py", line 39, in run_in_threadpool
    return await anyio.to_thread.run_sync(func, *args)
  File "C:\Users\carlo\anaconda3\envs\pasantias\lib\site-packages\anyio\to_thread.py", line 28, in run_sync
    return await get_asynclib().run_sync_in_worker_thread(func, *args, cancellable=cancellable,
  File "C:\Users\carlo\anaconda3\envs\pasantias\lib\site-packages\anyio\_backends\_asyncio.py", line 805, in run_sync_in_worker_thread
    return await future
  File "C:\Users\carlo\anaconda3\envs\pasantias\lib\site-packages\anyio\_backends\_asyncio.py", line 743, in run
    result = func(*args)
  File "C:\Users\carlo\Documents\GitHub\LompadS-Backend\.\main.py", line 114, in get_file
    FileController.write_data(''.join(open(f'./temp_files/{hashed_code}_exported.xml')).strip(),
FileNotFoundError: [Errno 2] No such file or directory: './temp_files/OA_Zotero_Scorm_6247207098006965764_exported.xml'
INFO:uvicorn.error:Shutting down
INFO:uvicorn.error:Waiting for application shutdown.
INFO:uvicorn.error:Application shutdown complete.
INFO:uvicorn.error:Finished server process [10764]
ERROR:root: Error: 'LOM' object has no attribute 'MetaMetaData'
ERROR:uvicorn.error:Exception in ASGI application
Traceback (most recent call last):
  File "C:\Users\carlo\anaconda3\envs\pasantias\lib\site-packages\uvicorn\protocols\http\h11_impl.py", line 373, in run_asgi
    result = await app(self.scope, self.receive, self.send)
  File "C:\Users\carlo\anaconda3\envs\pasantias\lib\site-packages\uvicorn\middleware\proxy_headers.py", line 75, in __call__
    return await self.app(scope, receive, send)
  File "C:\Users\carlo\anaconda3\envs\pasantias\lib\site-packages\fastapi\applications.py", line 208, in __call__
    await super().__call__(scope, receive, send)
  File "C:\Users\carlo\anaconda3\envs\pasantias\lib\site-packages\starlette\applications.py", line 112, in __call__
    await self.middleware_stack(scope, receive, send)
  File "C:\Users\carlo\anaconda3\envs\pasantias\lib\site-packages\starlette\middleware\errors.py", line 181, in __call__
    raise exc
  File "C:\Users\carlo\anaconda3\envs\pasantias\lib\site-packages\starlette\middleware\errors.py", line 159, in __call__
    await self.app(scope, receive, _send)
  File "C:\Users\carlo\anaconda3\envs\pasantias\lib\site-packages\starlette\middleware\cors.py", line 92, in __call__
    await self.simple_response(scope, receive, send, request_headers=headers)
  File "C:\Users\carlo\anaconda3\envs\pasantias\lib\site-packages\starlette\middleware\cors.py", line 147, in simple_response
    await self.app(scope, receive, send)
  File "C:\Users\carlo\anaconda3\envs\pasantias\lib\site-packages\starlette\exceptions.py", line 82, in __call__
    raise exc
  File "C:\Users\carlo\anaconda3\envs\pasantias\lib\site-packages\starlette\exceptions.py", line 71, in __call__
    await self.app(scope, receive, sender)
  File "C:\Users\carlo\anaconda3\envs\pasantias\lib\site-packages\starlette\routing.py", line 656, in __call__
    await route.handle(scope, receive, send)
  File "C:\Users\carlo\anaconda3\envs\pasantias\lib\site-packages\starlette\routing.py", line 259, in handle
    await self.app(scope, receive, send)
  File "C:\Users\carlo\anaconda3\envs\pasantias\lib\site-packages\starlette\routing.py", line 61, in app
    response = await func(request)
  File "C:\Users\carlo\anaconda3\envs\pasantias\lib\site-packages\fastapi\routing.py", line 226, in app
    raw_response = await run_endpoint_function(
  File "C:\Users\carlo\anaconda3\envs\pasantias\lib\site-packages\fastapi\routing.py", line 159, in run_endpoint_function
    return await dependant.call(**values)
  File "C:\Users\carlo\Documents\GitHub\LompadS-Backend\.\main.py", line 91, in read_file
    return {'DATA': FileController.load_recursive_model(xml_manifest, hashed_code)}
  File "C:\Users\carlo\Documents\GitHub\LompadS-Backend\.\controller\FileController.py", line 197, in load_recursive_model
    lom_controller.map_recursively(parsed_dictionary, is_lompad_exported=is_lompad_exported)
  File "C:\Users\carlo\Documents\GitHub\LompadS-Backend\.\controller\LOMController.py", line 43, in map_recursively
    self.map_recursively(dictionary[key], is_lompad_exported)
  File "C:\Users\carlo\Documents\GitHub\LompadS-Backend\.\controller\LOMController.py", line 40, in map_recursively
    self._mapped_data[key], self._object_dict[key] = LOMModel.determine_lompad_leaf(dictionary[key], str(key),
TypeError: cannot unpack non-iterable NoneType object
ERROR:uvicorn.error:Exception in ASGI application
Traceback (most recent call last):
  File "C:\Users\carlo\anaconda3\envs\pasantias\lib\site-packages\uvicorn\protocols\http\h11_impl.py", line 373, in run_asgi
    result = await app(self.scope, self.receive, self.send)
  File "C:\Users\carlo\anaconda3\envs\pasantias\lib\site-packages\uvicorn\middleware\proxy_headers.py", line 75, in __call__
    return await self.app(scope, receive, send)
  File "C:\Users\carlo\anaconda3\envs\pasantias\lib\site-packages\fastapi\applications.py", line 208, in __call__
    await super().__call__(scope, receive, send)
  File "C:\Users\carlo\anaconda3\envs\pasantias\lib\site-packages\starlette\applications.py", line 112, in __call__
    await self.middleware_stack(scope, receive, send)
  File "C:\Users\carlo\anaconda3\envs\pasantias\lib\site-packages\starlette\middleware\errors.py", line 181, in __call__
    raise exc
  File "C:\Users\carlo\anaconda3\envs\pasantias\lib\site-packages\starlette\middleware\errors.py", line 159, in __call__
    await self.app(scope, receive, _send)
  File "C:\Users\carlo\anaconda3\envs\pasantias\lib\site-packages\starlette\middleware\cors.py", line 92, in __call__
    await self.simple_response(scope, receive, send, request_headers=headers)
  File "C:\Users\carlo\anaconda3\envs\pasantias\lib\site-packages\starlette\middleware\cors.py", line 147, in simple_response
    await self.app(scope, receive, send)
  File "C:\Users\carlo\anaconda3\envs\pasantias\lib\site-packages\starlette\exceptions.py", line 82, in __call__
    raise exc
  File "C:\Users\carlo\anaconda3\envs\pasantias\lib\site-packages\starlette\exceptions.py", line 71, in __call__
    await self.app(scope, receive, sender)
  File "C:\Users\carlo\anaconda3\envs\pasantias\lib\site-packages\starlette\routing.py", line 656, in __call__
    await route.handle(scope, receive, send)
  File "C:\Users\carlo\anaconda3\envs\pasantias\lib\site-packages\starlette\routing.py", line 259, in handle
    await self.app(scope, receive, send)
  File "C:\Users\carlo\anaconda3\envs\pasantias\lib\site-packages\starlette\routing.py", line 61, in app
    response = await func(request)
  File "C:\Users\carlo\anaconda3\envs\pasantias\lib\site-packages\fastapi\routing.py", line 226, in app
    raw_response = await run_endpoint_function(
  File "C:\Users\carlo\anaconda3\envs\pasantias\lib\site-packages\fastapi\routing.py", line 161, in run_endpoint_function
    return await run_in_threadpool(dependant.call, **values)
  File "C:\Users\carlo\anaconda3\envs\pasantias\lib\site-packages\starlette\concurrency.py", line 39, in run_in_threadpool
    return await anyio.to_thread.run_sync(func, *args)
  File "C:\Users\carlo\anaconda3\envs\pasantias\lib\site-packages\anyio\to_thread.py", line 28, in run_sync
    return await get_asynclib().run_sync_in_worker_thread(func, *args, cancellable=cancellable,
  File "C:\Users\carlo\anaconda3\envs\pasantias\lib\site-packages\anyio\_backends\_asyncio.py", line 805, in run_sync_in_worker_thread
    return await future
  File "C:\Users\carlo\anaconda3\envs\pasantias\lib\site-packages\anyio\_backends\_asyncio.py", line 743, in run
    result = func(*args)
  File "C:\Users\carlo\Documents\GitHub\LompadS-Backend\.\main.py", line 114, in get_file
    FileController.write_data(''.join(open(f'./temp_files/{hashed_code}_exported.xml')).strip(),
FileNotFoundError: [Errno 2] No such file or directory: './temp_files/OA_Zotero_Scorm_-2540298700460132454_exported.xml'
ERROR:root: Error: 'LOM' object has no attribute 'MetaMetaData'
ERROR:uvicorn.error:Exception in ASGI application
Traceback (most recent call last):
  File "C:\Users\carlo\anaconda3\envs\pasantias\lib\site-packages\uvicorn\protocols\http\h11_impl.py", line 373, in run_asgi
    result = await app(self.scope, self.receive, self.send)
  File "C:\Users\carlo\anaconda3\envs\pasantias\lib\site-packages\uvicorn\middleware\proxy_headers.py", line 75, in __call__
    return await self.app(scope, receive, send)
  File "C:\Users\carlo\anaconda3\envs\pasantias\lib\site-packages\fastapi\applications.py", line 208, in __call__
    await super().__call__(scope, receive, send)
  File "C:\Users\carlo\anaconda3\envs\pasantias\lib\site-packages\starlette\applications.py", line 112, in __call__
    await self.middleware_stack(scope, receive, send)
  File "C:\Users\carlo\anaconda3\envs\pasantias\lib\site-packages\starlette\middleware\errors.py", line 181, in __call__
    raise exc
  File "C:\Users\carlo\anaconda3\envs\pasantias\lib\site-packages\starlette\middleware\errors.py", line 159, in __call__
    await self.app(scope, receive, _send)
  File "C:\Users\carlo\anaconda3\envs\pasantias\lib\site-packages\starlette\middleware\cors.py", line 92, in __call__
    await self.simple_response(scope, receive, send, request_headers=headers)
  File "C:\Users\carlo\anaconda3\envs\pasantias\lib\site-packages\starlette\middleware\cors.py", line 147, in simple_response
    await self.app(scope, receive, send)
  File "C:\Users\carlo\anaconda3\envs\pasantias\lib\site-packages\starlette\exceptions.py", line 82, in __call__
    raise exc
  File "C:\Users\carlo\anaconda3\envs\pasantias\lib\site-packages\starlette\exceptions.py", line 71, in __call__
    await self.app(scope, receive, sender)
  File "C:\Users\carlo\anaconda3\envs\pasantias\lib\site-packages\starlette\routing.py", line 656, in __call__
    await route.handle(scope, receive, send)
  File "C:\Users\carlo\anaconda3\envs\pasantias\lib\site-packages\starlette\routing.py", line 259, in handle
    await self.app(scope, receive, send)
  File "C:\Users\carlo\anaconda3\envs\pasantias\lib\site-packages\starlette\routing.py", line 61, in app
    response = await func(request)
  File "C:\Users\carlo\anaconda3\envs\pasantias\lib\site-packages\fastapi\routing.py", line 226, in app
    raw_response = await run_endpoint_function(
  File "C:\Users\carlo\anaconda3\envs\pasantias\lib\site-packages\fastapi\routing.py", line 159, in run_endpoint_function
    return await dependant.call(**values)
  File "C:\Users\carlo\Documents\GitHub\LompadS-Backend\.\main.py", line 91, in read_file
    return {'DATA': FileController.load_recursive_model(xml_manifest, hashed_code)}
  File "C:\Users\carlo\Documents\GitHub\LompadS-Backend\.\controller\FileController.py", line 197, in load_recursive_model
    lom_controller.map_recursively(parsed_dictionary, is_lompad_exported=is_lompad_exported)
  File "C:\Users\carlo\Documents\GitHub\LompadS-Backend\.\controller\LOMController.py", line 43, in map_recursively
    self.map_recursively(dictionary[key], is_lompad_exported)
  File "C:\Users\carlo\Documents\GitHub\LompadS-Backend\.\controller\LOMController.py", line 40, in map_recursively
    self._mapped_data[key], self._object_dict[key] = LOMModel.determine_lompad_leaf(dictionary[key], str(key),
TypeError: cannot unpack non-iterable NoneType object
ERROR:root: Error: 'LOM' object has no attribute 'MetaMetaData'
ERROR:uvicorn.error:Exception in ASGI application
Traceback (most recent call last):
  File "C:\Users\carlo\anaconda3\envs\pasantias\lib\site-packages\uvicorn\protocols\http\h11_impl.py", line 373, in run_asgi
    result = await app(self.scope, self.receive, self.send)
  File "C:\Users\carlo\anaconda3\envs\pasantias\lib\site-packages\uvicorn\middleware\proxy_headers.py", line 75, in __call__
    return await self.app(scope, receive, send)
  File "C:\Users\carlo\anaconda3\envs\pasantias\lib\site-packages\fastapi\applications.py", line 208, in __call__
    await super().__call__(scope, receive, send)
  File "C:\Users\carlo\anaconda3\envs\pasantias\lib\site-packages\starlette\applications.py", line 112, in __call__
    await self.middleware_stack(scope, receive, send)
  File "C:\Users\carlo\anaconda3\envs\pasantias\lib\site-packages\starlette\middleware\errors.py", line 181, in __call__
    raise exc
  File "C:\Users\carlo\anaconda3\envs\pasantias\lib\site-packages\starlette\middleware\errors.py", line 159, in __call__
    await self.app(scope, receive, _send)
  File "C:\Users\carlo\anaconda3\envs\pasantias\lib\site-packages\starlette\middleware\cors.py", line 92, in __call__
    await self.simple_response(scope, receive, send, request_headers=headers)
  File "C:\Users\carlo\anaconda3\envs\pasantias\lib\site-packages\starlette\middleware\cors.py", line 147, in simple_response
    await self.app(scope, receive, send)
  File "C:\Users\carlo\anaconda3\envs\pasantias\lib\site-packages\starlette\exceptions.py", line 82, in __call__
    raise exc
  File "C:\Users\carlo\anaconda3\envs\pasantias\lib\site-packages\starlette\exceptions.py", line 71, in __call__
    await self.app(scope, receive, sender)
  File "C:\Users\carlo\anaconda3\envs\pasantias\lib\site-packages\starlette\routing.py", line 656, in __call__
    await route.handle(scope, receive, send)
  File "C:\Users\carlo\anaconda3\envs\pasantias\lib\site-packages\starlette\routing.py", line 259, in handle
    await self.app(scope, receive, send)
  File "C:\Users\carlo\anaconda3\envs\pasantias\lib\site-packages\starlette\routing.py", line 61, in app
    response = await func(request)
  File "C:\Users\carlo\anaconda3\envs\pasantias\lib\site-packages\fastapi\routing.py", line 226, in app
    raw_response = await run_endpoint_function(
  File "C:\Users\carlo\anaconda3\envs\pasantias\lib\site-packages\fastapi\routing.py", line 159, in run_endpoint_function
    return await dependant.call(**values)
  File "C:\Users\carlo\Documents\GitHub\LompadS-Backend\.\main.py", line 91, in read_file
    return {'DATA': FileController.load_recursive_model(xml_manifest, hashed_code)}
  File "C:\Users\carlo\Documents\GitHub\LompadS-Backend\.\controller\FileController.py", line 197, in load_recursive_model
    lom_controller.map_recursively(parsed_dictionary, is_lompad_exported=is_lompad_exported)
  File "C:\Users\carlo\Documents\GitHub\LompadS-Backend\.\controller\LOMController.py", line 43, in map_recursively
    self.map_recursively(dictionary[key], is_lompad_exported)
  File "C:\Users\carlo\Documents\GitHub\LompadS-Backend\.\controller\LOMController.py", line 40, in map_recursively
    self._mapped_data[key], self._object_dict[key] = LOMModel.determine_lompad_leaf(dictionary[key], str(key),
TypeError: cannot unpack non-iterable NoneType object
ERROR:uvicorn.error:Exception in ASGI application
Traceback (most recent call last):
  File "C:\Users\carlo\anaconda3\envs\pasantias\lib\site-packages\uvicorn\protocols\http\h11_impl.py", line 373, in run_asgi
    result = await app(self.scope, self.receive, self.send)
  File "C:\Users\carlo\anaconda3\envs\pasantias\lib\site-packages\uvicorn\middleware\proxy_headers.py", line 75, in __call__
    return await self.app(scope, receive, send)
  File "C:\Users\carlo\anaconda3\envs\pasantias\lib\site-packages\fastapi\applications.py", line 208, in __call__
    await super().__call__(scope, receive, send)
  File "C:\Users\carlo\anaconda3\envs\pasantias\lib\site-packages\starlette\applications.py", line 112, in __call__
    await self.middleware_stack(scope, receive, send)
  File "C:\Users\carlo\anaconda3\envs\pasantias\lib\site-packages\starlette\middleware\errors.py", line 181, in __call__
    raise exc
  File "C:\Users\carlo\anaconda3\envs\pasantias\lib\site-packages\starlette\middleware\errors.py", line 159, in __call__
    await self.app(scope, receive, _send)
  File "C:\Users\carlo\anaconda3\envs\pasantias\lib\site-packages\starlette\middleware\cors.py", line 92, in __call__
    await self.simple_response(scope, receive, send, request_headers=headers)
  File "C:\Users\carlo\anaconda3\envs\pasantias\lib\site-packages\starlette\middleware\cors.py", line 147, in simple_response
    await self.app(scope, receive, send)
  File "C:\Users\carlo\anaconda3\envs\pasantias\lib\site-packages\starlette\exceptions.py", line 82, in __call__
    raise exc
  File "C:\Users\carlo\anaconda3\envs\pasantias\lib\site-packages\starlette\exceptions.py", line 71, in __call__
    await self.app(scope, receive, sender)
  File "C:\Users\carlo\anaconda3\envs\pasantias\lib\site-packages\starlette\routing.py", line 656, in __call__
    await route.handle(scope, receive, send)
  File "C:\Users\carlo\anaconda3\envs\pasantias\lib\site-packages\starlette\routing.py", line 259, in handle
    await self.app(scope, receive, send)
  File "C:\Users\carlo\anaconda3\envs\pasantias\lib\site-packages\starlette\routing.py", line 61, in app
    response = await func(request)
  File "C:\Users\carlo\anaconda3\envs\pasantias\lib\site-packages\fastapi\routing.py", line 226, in app
    raw_response = await run_endpoint_function(
  File "C:\Users\carlo\anaconda3\envs\pasantias\lib\site-packages\fastapi\routing.py", line 161, in run_endpoint_function
    return await run_in_threadpool(dependant.call, **values)
  File "C:\Users\carlo\anaconda3\envs\pasantias\lib\site-packages\starlette\concurrency.py", line 39, in run_in_threadpool
    return await anyio.to_thread.run_sync(func, *args)
  File "C:\Users\carlo\anaconda3\envs\pasantias\lib\site-packages\anyio\to_thread.py", line 28, in run_sync
    return await get_asynclib().run_sync_in_worker_thread(func, *args, cancellable=cancellable,
  File "C:\Users\carlo\anaconda3\envs\pasantias\lib\site-packages\anyio\_backends\_asyncio.py", line 805, in run_sync_in_worker_thread
    return await future
  File "C:\Users\carlo\anaconda3\envs\pasantias\lib\site-packages\anyio\_backends\_asyncio.py", line 743, in run
    result = func(*args)
  File "C:\Users\carlo\Documents\GitHub\LompadS-Backend\.\main.py", line 114, in get_file
    FileController.write_data(''.join(open(f'./temp_files/{hashed_code}_exported.xml')).strip(),
FileNotFoundError: [Errno 2] No such file or directory: './temp_files/OA_Zotero_Scorm_-7673459173798496839_exported.xml'
ERROR:root: Error: 'LOM' object has no attribute 'MetaMetaData'
ERROR:uvicorn.error:Exception in ASGI application
Traceback (most recent call last):
  File "C:\Users\carlo\anaconda3\envs\pasantias\lib\site-packages\uvicorn\protocols\http\h11_impl.py", line 373, in run_asgi
    result = await app(self.scope, self.receive, self.send)
  File "C:\Users\carlo\anaconda3\envs\pasantias\lib\site-packages\uvicorn\middleware\proxy_headers.py", line 75, in __call__
    return await self.app(scope, receive, send)
  File "C:\Users\carlo\anaconda3\envs\pasantias\lib\site-packages\fastapi\applications.py", line 208, in __call__
    await super().__call__(scope, receive, send)
  File "C:\Users\carlo\anaconda3\envs\pasantias\lib\site-packages\starlette\applications.py", line 112, in __call__
    await self.middleware_stack(scope, receive, send)
  File "C:\Users\carlo\anaconda3\envs\pasantias\lib\site-packages\starlette\middleware\errors.py", line 181, in __call__
    raise exc
  File "C:\Users\carlo\anaconda3\envs\pasantias\lib\site-packages\starlette\middleware\errors.py", line 159, in __call__
    await self.app(scope, receive, _send)
  File "C:\Users\carlo\anaconda3\envs\pasantias\lib\site-packages\starlette\middleware\cors.py", line 92, in __call__
    await self.simple_response(scope, receive, send, request_headers=headers)
  File "C:\Users\carlo\anaconda3\envs\pasantias\lib\site-packages\starlette\middleware\cors.py", line 147, in simple_response
    await self.app(scope, receive, send)
  File "C:\Users\carlo\anaconda3\envs\pasantias\lib\site-packages\starlette\exceptions.py", line 82, in __call__
    raise exc
  File "C:\Users\carlo\anaconda3\envs\pasantias\lib\site-packages\starlette\exceptions.py", line 71, in __call__
    await self.app(scope, receive, sender)
  File "C:\Users\carlo\anaconda3\envs\pasantias\lib\site-packages\starlette\routing.py", line 656, in __call__
    await route.handle(scope, receive, send)
  File "C:\Users\carlo\anaconda3\envs\pasantias\lib\site-packages\starlette\routing.py", line 259, in handle
    await self.app(scope, receive, send)
  File "C:\Users\carlo\anaconda3\envs\pasantias\lib\site-packages\starlette\routing.py", line 61, in app
    response = await func(request)
  File "C:\Users\carlo\anaconda3\envs\pasantias\lib\site-packages\fastapi\routing.py", line 226, in app
    raw_response = await run_endpoint_function(
  File "C:\Users\carlo\anaconda3\envs\pasantias\lib\site-packages\fastapi\routing.py", line 159, in run_endpoint_function
    return await dependant.call(**values)
  File "C:\Users\carlo\Documents\GitHub\LompadS-Backend\.\main.py", line 91, in read_file
    return {'DATA': FileController.load_recursive_model(xml_manifest, hashed_code)}
  File "C:\Users\carlo\Documents\GitHub\LompadS-Backend\.\controller\FileController.py", line 197, in load_recursive_model
    lom_controller.map_recursively(parsed_dictionary, is_lompad_exported=is_lompad_exported)
  File "C:\Users\carlo\Documents\GitHub\LompadS-Backend\.\controller\LOMController.py", line 43, in map_recursively
    self.map_recursively(dictionary[key], is_lompad_exported)
  File "C:\Users\carlo\Documents\GitHub\LompadS-Backend\.\controller\LOMController.py", line 40, in map_recursively
    self._mapped_data[key], self._object_dict[key] = LOMModel.determine_lompad_leaf(dictionary[key], str(key),
TypeError: cannot unpack non-iterable NoneType object
ERROR:uvicorn.error:Exception in ASGI application
Traceback (most recent call last):
  File "C:\Users\carlo\anaconda3\envs\pasantias\lib\site-packages\uvicorn\protocols\http\h11_impl.py", line 373, in run_asgi
    result = await app(self.scope, self.receive, self.send)
  File "C:\Users\carlo\anaconda3\envs\pasantias\lib\site-packages\uvicorn\middleware\proxy_headers.py", line 75, in __call__
    return await self.app(scope, receive, send)
  File "C:\Users\carlo\anaconda3\envs\pasantias\lib\site-packages\fastapi\applications.py", line 208, in __call__
    await super().__call__(scope, receive, send)
  File "C:\Users\carlo\anaconda3\envs\pasantias\lib\site-packages\starlette\applications.py", line 112, in __call__
    await self.middleware_stack(scope, receive, send)
  File "C:\Users\carlo\anaconda3\envs\pasantias\lib\site-packages\starlette\middleware\errors.py", line 181, in __call__
    raise exc
  File "C:\Users\carlo\anaconda3\envs\pasantias\lib\site-packages\starlette\middleware\errors.py", line 159, in __call__
    await self.app(scope, receive, _send)
  File "C:\Users\carlo\anaconda3\envs\pasantias\lib\site-packages\starlette\middleware\cors.py", line 92, in __call__
    await self.simple_response(scope, receive, send, request_headers=headers)
  File "C:\Users\carlo\anaconda3\envs\pasantias\lib\site-packages\starlette\middleware\cors.py", line 147, in simple_response
    await self.app(scope, receive, send)
  File "C:\Users\carlo\anaconda3\envs\pasantias\lib\site-packages\starlette\exceptions.py", line 82, in __call__
    raise exc
  File "C:\Users\carlo\anaconda3\envs\pasantias\lib\site-packages\starlette\exceptions.py", line 71, in __call__
    await self.app(scope, receive, sender)
  File "C:\Users\carlo\anaconda3\envs\pasantias\lib\site-packages\starlette\routing.py", line 656, in __call__
    await route.handle(scope, receive, send)
  File "C:\Users\carlo\anaconda3\envs\pasantias\lib\site-packages\starlette\routing.py", line 259, in handle
    await self.app(scope, receive, send)
  File "C:\Users\carlo\anaconda3\envs\pasantias\lib\site-packages\starlette\routing.py", line 61, in app
    response = await func(request)
  File "C:\Users\carlo\anaconda3\envs\pasantias\lib\site-packages\fastapi\routing.py", line 226, in app
    raw_response = await run_endpoint_function(
  File "C:\Users\carlo\anaconda3\envs\pasantias\lib\site-packages\fastapi\routing.py", line 161, in run_endpoint_function
    return await run_in_threadpool(dependant.call, **values)
  File "C:\Users\carlo\anaconda3\envs\pasantias\lib\site-packages\starlette\concurrency.py", line 39, in run_in_threadpool
    return await anyio.to_thread.run_sync(func, *args)
  File "C:\Users\carlo\anaconda3\envs\pasantias\lib\site-packages\anyio\to_thread.py", line 28, in run_sync
    return await get_asynclib().run_sync_in_worker_thread(func, *args, cancellable=cancellable,
  File "C:\Users\carlo\anaconda3\envs\pasantias\lib\site-packages\anyio\_backends\_asyncio.py", line 805, in run_sync_in_worker_thread
    return await future
  File "C:\Users\carlo\anaconda3\envs\pasantias\lib\site-packages\anyio\_backends\_asyncio.py", line 743, in run
    result = func(*args)
  File "C:\Users\carlo\Documents\GitHub\LompadS-Backend\.\main.py", line 114, in get_file
    FileController.write_data(''.join(open(f'./temp_files/{hashed_code}_exported.xml')).strip(),
FileNotFoundError: [Errno 2] No such file or directory: './temp_files/OA_Zotero_Scorm_-7707115617696701697_exported.xml'
ERROR:uvicorn.error:Exception in ASGI application
Traceback (most recent call last):
  File "C:\Users\carlo\anaconda3\envs\pasantias\lib\site-packages\uvicorn\protocols\http\h11_impl.py", line 373, in run_asgi
    result = await app(self.scope, self.receive, self.send)
  File "C:\Users\carlo\anaconda3\envs\pasantias\lib\site-packages\uvicorn\middleware\proxy_headers.py", line 75, in __call__
    return await self.app(scope, receive, send)
  File "C:\Users\carlo\anaconda3\envs\pasantias\lib\site-packages\fastapi\applications.py", line 208, in __call__
    await super().__call__(scope, receive, send)
  File "C:\Users\carlo\anaconda3\envs\pasantias\lib\site-packages\starlette\applications.py", line 112, in __call__
    await self.middleware_stack(scope, receive, send)
  File "C:\Users\carlo\anaconda3\envs\pasantias\lib\site-packages\starlette\middleware\errors.py", line 181, in __call__
    raise exc
  File "C:\Users\carlo\anaconda3\envs\pasantias\lib\site-packages\starlette\middleware\errors.py", line 159, in __call__
    await self.app(scope, receive, _send)
  File "C:\Users\carlo\anaconda3\envs\pasantias\lib\site-packages\starlette\middleware\cors.py", line 92, in __call__
    await self.simple_response(scope, receive, send, request_headers=headers)
  File "C:\Users\carlo\anaconda3\envs\pasantias\lib\site-packages\starlette\middleware\cors.py", line 147, in simple_response
    await self.app(scope, receive, send)
  File "C:\Users\carlo\anaconda3\envs\pasantias\lib\site-packages\starlette\exceptions.py", line 82, in __call__
    raise exc
  File "C:\Users\carlo\anaconda3\envs\pasantias\lib\site-packages\starlette\exceptions.py", line 71, in __call__
    await self.app(scope, receive, sender)
  File "C:\Users\carlo\anaconda3\envs\pasantias\lib\site-packages\starlette\routing.py", line 656, in __call__
    await route.handle(scope, receive, send)
  File "C:\Users\carlo\anaconda3\envs\pasantias\lib\site-packages\starlette\routing.py", line 259, in handle
    await self.app(scope, receive, send)
  File "C:\Users\carlo\anaconda3\envs\pasantias\lib\site-packages\starlette\routing.py", line 64, in app
    await response(scope, receive, send)
  File "C:\Users\carlo\anaconda3\envs\pasantias\lib\site-packages\starlette\responses.py", line 305, in __call__
    await send(
  File "C:\Users\carlo\anaconda3\envs\pasantias\lib\site-packages\starlette\exceptions.py", line 68, in sender
    await send(message)
  File "C:\Users\carlo\anaconda3\envs\pasantias\lib\site-packages\starlette\middleware\cors.py", line 153, in send
    await send(message)
  File "C:\Users\carlo\anaconda3\envs\pasantias\lib\site-packages\starlette\middleware\errors.py", line 156, in _send
    await send(message)
  File "C:\Users\carlo\anaconda3\envs\pasantias\lib\site-packages\uvicorn\protocols\http\h11_impl.py", line 477, in send
    output = self.conn.send(event)
  File "C:\Users\carlo\anaconda3\envs\pasantias\lib\site-packages\h11\_connection.py", line 468, in send
    data_list = self.send_with_data_passthrough(event)
  File "C:\Users\carlo\anaconda3\envs\pasantias\lib\site-packages\h11\_connection.py", line 501, in send_with_data_passthrough
    writer(event, data_list.append)
  File "C:\Users\carlo\anaconda3\envs\pasantias\lib\site-packages\h11\_writers.py", line 60, in __call__
    self.send_eom(event.headers, write)
  File "C:\Users\carlo\anaconda3\envs\pasantias\lib\site-packages\h11\_writers.py", line 83, in send_eom
    raise LocalProtocolError("Too little data for declared Content-Length")
h11._util.LocalProtocolError: Too little data for declared Content-Length
ERROR:uvicorn.error:Exception in ASGI application
Traceback (most recent call last):
  File "C:\Users\carlo\anaconda3\envs\pasantias\lib\site-packages\uvicorn\protocols\http\h11_impl.py", line 373, in run_asgi
    result = await app(self.scope, self.receive, self.send)
  File "C:\Users\carlo\anaconda3\envs\pasantias\lib\site-packages\uvicorn\middleware\proxy_headers.py", line 75, in __call__
    return await self.app(scope, receive, send)
  File "C:\Users\carlo\anaconda3\envs\pasantias\lib\site-packages\fastapi\applications.py", line 208, in __call__
    await super().__call__(scope, receive, send)
  File "C:\Users\carlo\anaconda3\envs\pasantias\lib\site-packages\starlette\applications.py", line 112, in __call__
    await self.middleware_stack(scope, receive, send)
  File "C:\Users\carlo\anaconda3\envs\pasantias\lib\site-packages\starlette\middleware\errors.py", line 181, in __call__
    raise exc
  File "C:\Users\carlo\anaconda3\envs\pasantias\lib\site-packages\starlette\middleware\errors.py", line 159, in __call__
    await self.app(scope, receive, _send)
  File "C:\Users\carlo\anaconda3\envs\pasantias\lib\site-packages\starlette\middleware\cors.py", line 92, in __call__
    await self.simple_response(scope, receive, send, request_headers=headers)
  File "C:\Users\carlo\anaconda3\envs\pasantias\lib\site-packages\starlette\middleware\cors.py", line 147, in simple_response
    await self.app(scope, receive, send)
  File "C:\Users\carlo\anaconda3\envs\pasantias\lib\site-packages\starlette\exceptions.py", line 82, in __call__
    raise exc
  File "C:\Users\carlo\anaconda3\envs\pasantias\lib\site-packages\starlette\exceptions.py", line 71, in __call__
    await self.app(scope, receive, sender)
  File "C:\Users\carlo\anaconda3\envs\pasantias\lib\site-packages\starlette\routing.py", line 656, in __call__
    await route.handle(scope, receive, send)
  File "C:\Users\carlo\anaconda3\envs\pasantias\lib\site-packages\starlette\routing.py", line 259, in handle
    await self.app(scope, receive, send)
  File "C:\Users\carlo\anaconda3\envs\pasantias\lib\site-packages\starlette\routing.py", line 64, in app
    await response(scope, receive, send)
  File "C:\Users\carlo\anaconda3\envs\pasantias\lib\site-packages\starlette\responses.py", line 305, in __call__
    await send(
  File "C:\Users\carlo\anaconda3\envs\pasantias\lib\site-packages\starlette\exceptions.py", line 68, in sender
    await send(message)
  File "C:\Users\carlo\anaconda3\envs\pasantias\lib\site-packages\starlette\middleware\cors.py", line 153, in send
    await send(message)
  File "C:\Users\carlo\anaconda3\envs\pasantias\lib\site-packages\starlette\middleware\errors.py", line 156, in _send
    await send(message)
  File "C:\Users\carlo\anaconda3\envs\pasantias\lib\site-packages\uvicorn\protocols\http\h11_impl.py", line 477, in send
    output = self.conn.send(event)
  File "C:\Users\carlo\anaconda3\envs\pasantias\lib\site-packages\h11\_connection.py", line 468, in send
    data_list = self.send_with_data_passthrough(event)
  File "C:\Users\carlo\anaconda3\envs\pasantias\lib\site-packages\h11\_connection.py", line 501, in send_with_data_passthrough
    writer(event, data_list.append)
  File "C:\Users\carlo\anaconda3\envs\pasantias\lib\site-packages\h11\_writers.py", line 60, in __call__
    self.send_eom(event.headers, write)
  File "C:\Users\carlo\anaconda3\envs\pasantias\lib\site-packages\h11\_writers.py", line 83, in send_eom
    raise LocalProtocolError("Too little data for declared Content-Length")
h11._util.LocalProtocolError: Too little data for declared Content-Length
INFO:uvicorn.error:Shutting down
